<mujoco>

<default>
    <joint axis = "0 0 1" type = "hinge" limited = "false" damping = "0.2"/>
</default>

<worldbody>
    <light name = "top" pos ="0 0 1"/>
    <body name = "body1" pos = "0 0 0">
        <joint name ="joint1_z"/>
        <joint name ="joint1_x" axis = "1 0 0"/>
        <joint name ="joint1_y" axis = "0 1 0"/>
        <geom size = ".1 .1 .1" type = "box" rgba=".8 .1 .1 1"/>
    </body>
    <body name = "body2" pos = ".5 0 0" euler="0 0 0">
        <joint name ="joint2"/>
        <geom size = ".1 .2 .3" type = "box" rgba=".1 .8 .1 1"/>
    </body>
    <body name = "body3" pos = "1.0 0 0" euler="45 0 0">
        <joint name ="joint3" axis = "1 0 0" springdamper = "1 1"/>
        <geom size = ".3 .2 .1" type = "box" rgba=".1 .1 .8 1"/>
    </body>
</worldbody>

<actuator>
    <position name ="act1_x" joint="joint1_x"/>
    <position name ="act1_y" joint="joint1_y"/>
    <position name ="act1_z" joint="joint1_z"/>
    <position name ="act2" joint="joint2"/>
    <position name ="act3" joint="joint3"/>
</actuator>

</mujoco>