<robot name="two_bodies" xmlns:xacro="http://ros.org/wiki/xacro">
  <mujoco>
    <compiler 
    balanceinertia="true" 
    discardvisual="false"
    meshdir = "meshes" 
    fusestatic="false"/>
  </mujoco>

  <!-- fixed body -->
  <link name="world">  
  </link>

  <!-- body one -->
  <link name="body_one">
    <inertial>
      <origin xyz="0 0 0" rpy="0 0 0" />
      <mass value="62.4" />
      <inertia
        ixx="0.26" ixy="0" ixz="0"
        iyy="0.884" iyz="0"   
        izz="1.04" />
    </inertial>
    <visual>
      <origin xyz="0 0 0" rpy="0 0 0" />
      <geometry>
        <box size=".4 .2 .1" />
      </geometry> 
      <material name="blue">
        <color rgba=".15 0.15 .85 1"/>
      </material>
    </visual>
    <collision>
      <geometry>
          <box size=".4 .2 .1"/>
      </geometry> 
    </collision>
  </link>

  <!-- body two -->
  <link name="body_two">
    <inertial>
      <origin xyz="0 0 0" rpy="0 0 0" />
      <mass value="5" />
      <inertia
        ixx="2.94524311e-06" ixy="0" ixz="0"
        iyy="2.94524311e-06" iyz="0"   
        izz="1.47262156e-06" />
    </inertial>
    <visual>
      <origin xyz="0 0 0" rpy="0 0 0" />
      <geometry>
        <cylinder radius=".05"  length=".15" />
      </geometry> 
      <material name="red">
        <color rgba=".85 .15 .15 1"/>
      </material>
    </visual>
    <collision>
      <geometry>
        <cylinder radius=".05"  length=".15" />
      </geometry>
    </collision>
  </link>

    <!-- body three -->
  <link name="body_three">
    <inertial>
      <origin xyz="0 0 0" rpy="0 0 0" />
      <mass value="5" />
      <inertia
        ixx="2.94524311e-06" ixy="0" ixz="0"
        iyy="2.94524311e-06" iyz="0"   
        izz="1.47262156e-06" />
    </inertial>
    <visual>
      <origin xyz="0 0 0" rpy="0 0 0" />
      <geometry>
        <sphere radius=".05" />
      </geometry> 
      <material name="green">
        <color rgba=".15 .85 .15 1"/>
      </material>
    </visual>
    <collision>
      <geometry>
        <cylinder radius=".05"  length=".15" />
      </geometry>
    </collision>
  </link>

  <joint name="fixed_joint" type="fixed">
    <origin rpy="0 0 0" xyz="0 0 0"/>
    <parent link="world"/>
    <child link="body_one"/>
  </joint>

  <joint name="floating_joint_cylinder" type="floating">
    <origin rpy="1 .5 0" xyz=".15 .05 0.2"/>
    <parent link="world"/>
    <child link="body_two"/>
  </joint>

  <joint name="floating_joint_sphere" type="floating">
    <origin rpy="0 0 0" xyz="-.15 -.05 0.2"/>
    <parent link="world"/>
    <child link="body_three"/>
  </joint>

</robot>