
<mujoco>
    <option gravity="0 0 -9.8" solver="CG"/>
    <compiler balanceinertia="true" autolimits="true"/>
    <default>
        <site rgba="1 1 1 1"/>
        <tendon stiffness="0.06" width=".003" damping="0.1"/>
    </default>    
    
    <visual>
        <global azimuth="180" elevation="0"/>
    </visual>
    
    <asset>
        <texture name="grid" type="2d" builtin="checker" width="512" height="512" rgb1=".5 .5 .5" rgb2="1 1 1"/>
        <material name="grid" texture="grid" texrepeat="1 1" texuniform="true" reflectance=".2"/>
        <material name="global_tendor" rgba="1 0 0 1" />
        <material name="flexor_tendon_knee" rgba="0 0 1 1" />
        <material name="extensor_tendon_1" rgba="0 0.6 0 1" />
        <material name="extensor_tendon_2" rgba="0 1 0 1" />
        <material name="disengagement_flexor_tendon" rgba="1 0.5 0 1" />
        <material name="virtual_elements" rgba="0 0 0 0.001" />
        
        <material name="links" rgba="0.75 0.75 0.75 0.3" />
        <material name="joints" rgba="0.75 0.75 0.75 0.3" />
    </asset>
    
    <worldbody>
        <geom type="plane" size="1 1 0.1" pos="0 0 -0.3145" material="grid" />
        <light diffuse=".5 .5 .5" pos="0 0 3" dir="0 0 -1" />
        <body name="base" pos="0 0 0">
            <joint type="slide" axis="0 0 1"/>
            <geom type="box" size="0.025 0.0475 0.05775" rgba="0.75 0.75 0.75 0.3"/>
            <body name="knee_joint" pos="0 -0.03 0.032">
                <joint name="joint_0" type="slide" pos="0 0 0" axis="0 0 1" range="-0.01 0.1" damping="1"/>
                <geom type="capsule" size="0.0033333333333333335 0.0033333333333333335" pos="0 0 0" euler="0 90 0" material="joints" />
                <site name="s01" pos="0 0 0"/>
            </body>
            <geom name="j0" type="cylinder" size="0.01 0.01" pos="0 -0.02 0.022" euler="0 90 0" material="joints" />
            <site name="s02" pos="0 -0.03 0.022"/>    
            <site name="s03" pos="0 -0.0475 0"/>
            <body name="link_1" pos="0 -0.02 -0.022">
    			<geom type="box" size="0.01" fromto="0 0 0 0 0.02083493313075292 -0.07775702901627" material="links"/>
    			<geom type="cylinder" size="0.01 0.01" pos="0 0 0" euler="0 90 0" material="joints" />
    			<geom name="j1" type="cylinder" size="0.01 0.01" pos="0 0.02083493313075292 -0.07775702901627" euler="0 90 0" material="joints" />
    			<joint name="joint_1" pos="0 0 0" axis="1 0 0" />
                <site name="s11" pos="0 0 0"/>
                <site name="s12" pos="0 0.030834933130752917 -0.07775702901627"/>
                <body name="link_2" pos="0 0.02083493313075292 -0.07775702901627">
    				<geom type="box" size="0.01" fromto="0 0 0 0 -0.056982971031044306 -0.09409006861765574" material="links"/>
    				<geom type="cylinder" size="0.01 0.01" pos="0 0 0" euler="0 90 0" material="joints" />
    				<geom name="j2" type="cylinder" size="0.01 0.01" pos="0 -0.056982971031044306 -0.09409006861765574" euler="0 90 0" material="joints" />
    				<joint name="joint_2" pos="0 0 0" axis="1 0 0" />
                    <site name="s21" pos="0 -0.004245742757761076 -0.023522517154413936"/>
                    <site name="s22" pos="0 -0.018491485515522155 -0.04704503430882787"/>
                    <site name="s23" pos="0 -0.03273722827328323 -0.07056755146324181"/>
                    <site name="s24" pos="0 -0.046982971031044304 -0.09409006861765574"/>
                    <site name="s25" pos="0 -0.06698297103104431 -0.09409006861765574"/>
                </body>
                <body name="link_3" pos="0 0.012940952255126037 -0.04829629131445342">
    				<geom type="box" size="0.01" fromto="0 0 0 0 -0.056982971031044306 -0.09409006861765574" material="links"/>
    				<geom type="cylinder" size="0.01 0.01" pos="0 0 0" euler="0 90 0" material="joints" />
    				<geom type="cylinder" size="0.01 0.01" pos="0 -0.056982971031044306 -0.09409006861765574" euler="0 90 0" material="joints" />
    				<joint name="joint_3" pos="0 0 0" axis="1 0 0" />
                    <body name="link_4" pos="0 -0.056982971031044306 -0.09409006861765574">
    					<geom type="box" size="0.01" fromto="0 0 0 0 0.029026035496191004 -0.10610131603035779" material="links"/>
    					<geom type="cylinder" size="0.01 0.01" pos="0 0 0" euler="0 90 0" material="joints" />
    					<geom name="j4" type="cylinder" size="0.01 0.01" pos="0 0.029026035496191004 -0.10610131603035779" euler="0 90 0" material="joints" />
    					<joint name="joint_4" pos="0 0 0" axis="1 0 0" />
                        <site name="s41" pos="0 0.019026035496191 -0.10610131603035779"/>
                        <site name="s42" pos="0 0.039026035496191006 -0.10610131603035779"/>
                        <site name="s43" pos="0 0.0245130177480955 -0.05305065801517889"/>
                        <body name="link_5" pos="0 0.029026035496191004 -0.10610131603035779">
    						<geom type="box" size="0.01" fromto="0 0 0 0 0.022943057454041845 -0.03276608177155967" material="links"/>
    						<geom type="cylinder" size="0.01 0.01" pos="0 0 0" euler="0 90 0" material="joints" />
    						<geom name="j5" type="cylinder" size="0.01 0.01" pos="0 0.022943057454041845 -0.03276608177155967" euler="0 90 0" material="joints" />
    						<joint name="joint_5" pos="0 0 0" axis="1 0 0" limited="true" range="-30 30"/>
                            <site name="s51" pos="0 0.012943057454041845 -0.03276608177155967"/>
                            <site name="s52" pos="0 0.032943057454041844 -0.03276608177155967"/>
                            <body name="link_6" pos="0 0.022943057454041845 -0.03276608177155967">
    							<geom type="box" size="0.01" fromto="0 0 0 0 0.02 0.0" material="links"/>
    							<geom type="cylinder" size="0.01 0.01" pos="0 0 0" euler="0 90 0" material="joints" />
    							<geom type="cylinder" size="0.01 0.01" pos="0 0.02 0.0" euler="0 90 0" material="joints" />
    							<joint name="joint_6" pos="0 0 0" axis="1 0 0" limited="true" range="-30 30"/>
                                <site name="s61" pos="0 0.013333333333333332 0.0"/>
                            </body>                        
                        </body>
                    </body>
                </body>
            </body>
        </body>

    </worldbody>
    
    <equality>
        <connect name="kinematic_link" active="true" body1="link_2" body2="link_4" anchor="0 -0.056982971031044306 -0.09409006861765574" />
    </equality>

    <actuator>
        <position name="knee_motor" joint="joint_0" kp="10"/>
        <position name="hip_motor" joint="joint_1" kp="100"/>
    </actuator>
    
    <tendon>
        <spatial name="flexor_tendon_knee" material="flexor_tendon_knee" stiffness="500">
            <site site="s01"/>
            <geom geom="j0" sidesite="s02"/>
            <site site="s21"/>
        </spatial>
    </tendon>
    <tendon>
        <spatial name="global_tendor" material="global_tendor">
            <site site="s03"/>
            <site site="s11"/>
            <site site="s12"/>
            <geom geom="j1" sidesite="s12"/>
            <site site="s25"/>
            <site site="s41"/>
            <geom geom="j4" sidesite="s41"/>
            <site site="s51"/>
            <geom geom="j5" sidesite="s51"/>
            <site site="s61"/>
        </spatial>
        <spatial name="extensor_tendon_1" material="extensor_tendon_1">
            <site site="s22"/>
            <site site="s24"/>
            <site site="s42"/>
        </spatial>
        <spatial name="extensor_tendon_2" material="extensor_tendon_2">
            <site site="s23"/>
            <site site="s24"/>
            <site site="s42"/>
            <site site="s61"/>
        </spatial>
        <spatial name="disengagement_flexor_tendon" material="disengagement_flexor_tendon">
            <site site="s43"/>
            <site site="s41"/>
            <geom geom="j4" sidesite="s41"/>
            <site site="s51"/>
            <geom geom="j5" sidesite="s51"/>
            <site site="s61"/>
        </spatial>
    </tendon>
</mujoco>
