<mujoco>
    <option gravity = "0 0 0" timestep = "0.002" />
	<worldbody>

        <light diffuse=".5 .5 .5" pos="0 0 2" dir="0 0 -1"/>

		<geom type="plane" size="2 2 0.1" rgba="0.9 0.9 0.9 1"/>

		<body pos="0.5 0 0.1" euler = "0 90 0">
			<joint type="hinge" name="joint_A" axis = "-1 0 0" pos = "0 0 -0.5"/>
			<geom type="cylinder" size=".05 .5" rgba=".9 .2 .2 1"/>
			<site name="com" size="0.07" pos="0 0 0"/>
            <body pos="0 0 1" euler = "0 0 0">
			    <joint type="hinge" name="joint_B" axis = "-1 0 0" pos = "0 0 -0.5"/>
			    <geom type="cylinder" size=".05 .5" rgba=".2 .9 .2 1"/>
		    	<site name='tip' size = "0.1" pos = "0 0 0.5"/>
			</body>
		</body>

	</worldbody>
	<sensor>
		<framepos objtype="site" objname ="tip"/>
		<framepos objtype="site" objname ="com"/>
	</sensor>
	<actuator>
		<velocity name = "first" joint="joint_A" kv="100" />
		<velocity name = "second" joint="joint_B" kv="100" />
	</actuator>
</mujoco>
